<?xml version="1.0" ?>
<!-- =================================================================================== -->
<!-- |    This document was autogenerated by xacro from gen3_lite_bullet_macro.xacro   | -->
<!-- |    EDITING THIS FILE BY HAND IS NOT RECOMMENDED                                 | -->
<!-- =================================================================================== -->
<robot name="gen3_lite_arm_pybullet">
  <ros2_control name="GenericSystem" type="system">
    <hardware>
      <plugin>mock_components/GenericSystem</plugin>
      <param name="fake_sensor_commands">False</param>
      <param name="state_following_offset">0.0</param>
    </hardware>
    <joint name="gen3_joint_1">
      <command_interface name="position">
        <param name="min">-2.69</param>
        <param name="max">2.69</param>
      </command_interface>
      <state_interface name="position">
        <param name="initial_value">0.0</param>
      </state_interface>
      <state_interface name="velocity"/>
      <state_interface name="effort"/>
    </joint>
    <joint name="gen3_joint_2">
      <command_interface name="position">
        <param name="min">-2.69</param>
        <param name="max">2.36</param>
      </command_interface>
      <state_interface name="position">
        <param name="initial_value">0.0</param>
      </state_interface>
      <state_interface name="velocity"/>
      <state_interface name="effort"/>
    </joint>
    <joint name="gen3_joint_3">
      <command_interface name="position">
        <param name="min">-2.69</param>
        <param name="max">2.69</param>
      </command_interface>
      <state_interface name="position">
        <param name="initial_value">0.0</param>
      </state_interface>
      <state_interface name="velocity"/>
      <state_interface name="effort"/>
    </joint>
    <joint name="gen3_joint_4">
      <command_interface name="position">
        <param name="min">-2.59</param>
        <param name="max">2.59</param>
      </command_interface>
      <state_interface name="position">
        <param name="initial_value">0.0</param>
      </state_interface>
      <state_interface name="velocity"/>
      <state_interface name="effort"/>
    </joint>
    <joint name="gen3_joint_5">
      <command_interface name="position">
        <param name="min">-2.57</param>
        <param name="max">2.57</param>
      </command_interface>
      <state_interface name="position">
        <param name="initial_value">0.0</param>
      </state_interface>
      <state_interface name="velocity"/>
      <state_interface name="effort"/>
    </joint>
    <joint name="gen3_joint_6">
      <command_interface name="position">
        <param name="min">-2.59</param>
        <param name="max">2.59</param>
      </command_interface>
      <state_interface name="position">
        <param name="initial_value">0.0</param>
      </state_interface>
      <state_interface name="velocity"/>
      <state_interface name="effort"/>
    </joint>
  </ros2_control>
  <joint name="gen3_base_joint" type="fixed">
    <origin rpy="0 0 0" xyz="0 0 0"/>
    <parent link="world"/>
    <child link="gen3_base_link"/>
  </joint>
  <link name="gen3_base_link">
    <inertial>
      <origin rpy="0 0 0" xyz="0.00244324 0.00015573 0.08616742"/>
      <mass value="1.14608471"/>
      <inertia ixx="0.00335854" ixy="3.9E-07" ixz="0.00010989" iyy="0.003311" iyz="1.91E-06" izz="0.00077158"/>
    </inertial>
    <visual>
      <origin rpy="0 0 0" xyz="0 0 0"/>
      <geometry>
        <mesh filename="package://kortex_description/arms/gen3_lite/6dof/meshes/base_link.STL"/>
      </geometry>
      <material name="">
        <color rgba="0.803 0.824 0.820 1"/>
      </material>
    </visual>
    <collision>
      <origin rpy="0 0 0" xyz="0 0 0"/>
      <geometry>
        <mesh filename="package://kortex_description/arms/gen3_lite/6dof/meshes/base_link.STL"/>
      </geometry>
    </collision>
  </link>
  <gazebo reference="gen3_base_link">
    <material>Kortex/Gray</material>
  </gazebo>
  <link name="gen3_shoulder_link">
    <inertial>
      <origin rpy="0 0 0" xyz="2.477E-05 0.02213531 0.09937686"/>
      <mass value="0.95974404"/>
      <inertia ixx="0.00165947" ixy="2E-08" ixz="3.6E-07" iyy="0.00140355" iyz="0.00034927" izz="0.00089493"/>
    </inertial>
    <visual>
      <origin rpy="0 0 0" xyz="0 0 0"/>
      <geometry>
        <mesh filename="package://kortex_description/arms/gen3_lite/6dof/meshes/shoulder_link.STL"/>
      </geometry>
      <material name="">
        <color rgba="0.803 0.824 0.820 1"/>
      </material>
    </visual>
    <collision>
      <origin rpy="0 0 0" xyz="0 0 0"/>
      <geometry>
        <mesh filename="package://kortex_description/arms/gen3_lite/6dof/meshes/shoulder_link.STL"/>
      </geometry>
    </collision>
  </link>
  <gazebo reference="gen3_shoulder_link">
    <material>Kortex/Gray</material>
  </gazebo>
  <joint name="gen3_joint_1" type="revolute">
    <origin rpy="0 0 0" xyz="0 0 0.12825"/>
    <parent link="gen3_base_link"/>
    <child link="gen3_shoulder_link"/>
    <axis xyz="0 0 1"/>
    <limit effort="10" lower="-2.68" upper="2.68" velocity="1.6"/>
  </joint>
  <link name="gen3_arm_link">
    <inertial>
      <origin rpy="0 0 0" xyz="0.02998299 0.21154808 0.0453031"/>
      <mass value="1.17756164"/>
      <inertia ixx="0.01149277" ixy="1E-06" ixz="1.6E-07" iyy="0.00102851" iyz="0.00140765" izz="0.01133492"/>
    </inertial>
    <visual>
      <origin rpy="0 0 0" xyz="0 0 0"/>
      <geometry>
        <mesh filename="package://kortex_description/arms/gen3_lite/6dof/meshes/arm_link.STL"/>
      </geometry>
      <material name="">
        <color rgba="0.803 0.824 0.820 1"/>
      </material>
    </visual>
    <collision>
      <origin rpy="0 0 0" xyz="0 0 0"/>
      <geometry>
        <mesh filename="package://kortex_description/arms/gen3_lite/6dof/meshes/arm_link.STL"/>
      </geometry>
    </collision>
  </link>
  <gazebo reference="gen3_arm_link">
    <material>Kortex/Gray</material>
  </gazebo>
  <joint name="gen3_joint_2" type="revolute">
    <origin rpy="1.5708 0 0" xyz="0 -0.03 0.115"/>
    <parent link="gen3_shoulder_link"/>
    <child link="gen3_arm_link"/>
    <axis xyz="0 0 1"/>
    <limit effort="14" lower="-2.61" upper="2.61" velocity="1.6"/>
  </joint>
  <link name="gen3_forearm_link">
    <inertial>
      <origin rpy="0 0 0" xyz="0.0301559 0.09502206 0.0073555"/>
      <mass value="0.59767669"/>
      <inertia ixx="0.00163256" ixy="7.11E-06" ixz="1.54E-06" iyy="0.00029798" iyz="9.587E-05" izz="0.00169091"/>
    </inertial>
    <visual>
      <origin rpy="0 0 0" xyz="0 0 0"/>
      <geometry>
        <mesh filename="package://kortex_description/arms/gen3_lite/6dof/meshes/forearm_link.STL"/>
      </geometry>
      <material name="">
        <color rgba="0.803 0.824 0.820 1"/>
      </material>
    </visual>
    <collision>
      <origin rpy="0 0 0" xyz="0 0 0"/>
      <geometry>
        <mesh filename="package://kortex_description/arms/gen3_lite/6dof/meshes/forearm_link.STL"/>
      </geometry>
    </collision>
  </link>
  <gazebo reference="gen3_forearm_link">
    <material>Kortex/Gray</material>
  </gazebo>
  <joint name="gen3_joint_3" type="revolute">
    <origin rpy="-3.1416 0 0" xyz="0 0.28 0"/>
    <parent link="gen3_arm_link"/>
    <child link="gen3_forearm_link"/>
    <axis xyz="0 0 1"/>
    <limit effort="10" lower="-2.61" upper="2.61" velocity="1.6"/>
  </joint>
  <link name="gen3_lower_wrist_link">
    <inertial>
      <origin rpy="0 0 0" xyz="0.00575149 0.01000443 0.08719207"/>
      <mass value="0.52693412"/>
      <inertia ixx="0.00069098" ixy="2.4E-07" ixz="0.00016483" iyy="0.00078519" iyz="7.4E-07" izz="0.00034115"/>
    </inertial>
    <visual>
      <origin rpy="0 0 0" xyz="0 0 0"/>
      <geometry>
        <mesh filename="package://kortex_description/arms/gen3_lite/6dof/meshes/lower_wrist_link.STL"/>
      </geometry>
      <material name="">
        <color rgba="0.803 0.824 0.820 1"/>
      </material>
    </visual>
    <collision>
      <origin rpy="0 0 0" xyz="0 0 0"/>
      <geometry>
        <mesh filename="package://kortex_description/arms/gen3_lite/6dof/meshes/lower_wrist_link.STL"/>
      </geometry>
    </collision>
  </link>
  <gazebo reference="gen3_lower_wrist_link">
    <material>Kortex/Gray</material>
  </gazebo>
  <joint name="gen3_joint_4" type="revolute">
    <origin rpy="1.5708 0 0" xyz="0 -0.14 0.02"/>
    <parent link="gen3_forearm_link"/>
    <child link="gen3_lower_wrist_link"/>
    <axis xyz="0 0 1"/>
    <limit effort="7" lower="-2.6" upper="2.6" velocity="1.6"/>
  </joint>
  <link name="gen3_upper_wrist_link">
    <inertial>
      <origin rpy="0 0 0" xyz="0.08056517 0.00980409 0.01872799"/>
      <mass value="0.58097325"/>
      <inertia ixx="0.00021268" ixy="5.21E-06" ixz="2.91E-06" iyy="0.00106371" iyz="1.1E-07" izz="0.00108465"/>
    </inertial>
    <visual>
      <origin rpy="0 0 0" xyz="0 0 0"/>
      <geometry>
        <mesh filename="package://kortex_description/arms/gen3_lite/6dof/meshes/upper_wrist_link.STL"/>
      </geometry>
      <material name="">
        <color rgba="0.803 0.824 0.820 1"/>
      </material>
    </visual>
    <collision>
      <origin rpy="0 0 0" xyz="0 0 0"/>
      <geometry>
        <mesh filename="package://kortex_description/arms/gen3_lite/6dof/meshes/upper_wrist_link.STL"/>
      </geometry>
    </collision>
  </link>
  <gazebo reference="gen3_upper_wrist_link">
    <material>Kortex/Gray</material>
  </gazebo>
  <joint name="gen3_joint_5" type="revolute">
    <origin rpy="0 1.5708 0" xyz="0.0285 0 0.105"/>
    <parent link="gen3_lower_wrist_link"/>
    <child link="gen3_upper_wrist_link"/>
    <axis xyz="0 0 1"/>
    <limit effort="7" lower="-2.53" upper="2.53" velocity="1.6"/>
  </joint>
  <link name="gen3_end_effector_link"/>
  <joint name="gen3_joint_6" type="revolute">
    <origin rpy="0 -1.5708 0" xyz="-0.105 0 0.0285"/>
    <parent link="gen3_upper_wrist_link"/>
    <child link="gen3_end_effector_link"/>
    <axis xyz="0 0 1"/>
    <limit effort="7" lower="-2.6" upper="2.6" velocity="3.2"/>
  </joint>
  <link name="gen3_dummy_link"/>
  <joint name="gen3_end_effector" type="fixed">
    <origin rpy="0 0 0" xyz="0 0 0"/>
    <parent link="gen3_end_effector_link"/>
    <child link="gen3_dummy_link"/>
    <axis xyz="0 0 1"/>
    <limit effort="0" lower="0" upper="0" velocity="0"/>
  </joint>
</robot>
